Microsoft Windows [Version 10.0.17134.523]
(c) 2018 Microsoft Corporation. All rights reserved.

C:\Users\J-Coders-Pc4>cd desktop

C:\Users\J-Coders-Pc4\Desktop>cd ditari

C:\Users\J-Coders-Pc4\Desktop\ditari>python manage.py runserver
Unhandled exception in thread started by <function check_errors.<locals>.wrapper at 0x04757078>
Traceback (most recent call last):
  File "C:\Program Files (x86)\Python37-32\lib\site-packages\django\utils\autoreload.py", line 225, in wrapper
    fn(*args, **kwargs)
  File "C:\Program Files (x86)\Python37-32\lib\site-packages\django\core\management\commands\runserver.py", line 109, in inner_run
    autoreload.raise_last_exception()
  File "C:\Program Files (x86)\Python37-32\lib\site-packages\django\utils\autoreload.py", line 248, in raise_last_exception
    raise _exception[1]
  File "C:\Program Files (x86)\Python37-32\lib\site-packages\django\core\management\__init__.py", line 337, in execute
    autoreload.check_errors(django.setup)()
  File "C:\Program Files (x86)\Python37-32\lib\site-packages\django\utils\autoreload.py", line 225, in wrapper
    fn(*args, **kwargs)
  File "C:\Program Files (x86)\Python37-32\lib\site-packages\django\__init__.py", line 24, in setup
    apps.populate(settings.INSTALLED_APPS)
  File "C:\Program Files (x86)\Python37-32\lib\site-packages\django\apps\registry.py", line 112, in populate
    app_config.import_models()
  File "C:\Program Files (x86)\Python37-32\lib\site-packages\django\apps\config.py", line 198, in import_models
    self.models_module = import_module(models_module_name)
  File "C:\Program Files (x86)\Python37-32\lib\importlib\__init__.py", line 127, in import_module
    return _bootstrap._gcd_import(name[level:], package, level)
  File "<frozen importlib._bootstrap>", line 1006, in _gcd_import
  File "<frozen importlib._bootstrap>", line 983, in _find_and_load
  File "<frozen importlib._bootstrap>", line 967, in _find_and_load_unlocked
  File "<frozen importlib._bootstrap>", line 677, in _load_unlocked
  File "<frozen importlib._bootstrap_external>", line 724, in exec_module
  File "<frozen importlib._bootstrap_external>", line 860, in get_code
  File "<frozen importlib._bootstrap_external>", line 791, in source_to_code
  File "<frozen importlib._bootstrap>", line 219, in _call_with_frames_removed
  File "C:\Users\J-Coders-Pc4\Desktop\ditari\home\models.py", line 25
    return self.emriKlasa+"/"+self.paralelja
                                           ^
TabError: inconsistent use of tabs and spaces in indentation
Unhandled exception in thread started by <function check_errors.<locals>.wrapper at 0x03E070C0>
Traceback (most recent call last):
  File "C:\Program Files (x86)\Python37-32\lib\site-packages\django\utils\autoreload.py", line 225, in wrapper
    fn(*args, **kwargs)
  File "C:\Program Files (x86)\Python37-32\lib\site-packages\django\core\management\commands\runserver.py", line 109, in inner_run
    autoreload.raise_last_exception()
  File "C:\Program Files (x86)\Python37-32\lib\site-packages\django\utils\autoreload.py", line 248, in raise_last_exception
    raise _exception[1]
  File "C:\Program Files (x86)\Python37-32\lib\site-packages\django\core\management\__init__.py", line 337, in execute
    autoreload.check_errors(django.setup)()
  File "C:\Program Files (x86)\Python37-32\lib\site-packages\django\utils\autoreload.py", line 225, in wrapper
    fn(*args, **kwargs)
  File "C:\Program Files (x86)\Python37-32\lib\site-packages\django\__init__.py", line 24, in setup
    apps.populate(settings.INSTALLED_APPS)
  File "C:\Program Files (x86)\Python37-32\lib\site-packages\django\apps\registry.py", line 112, in populate
    app_config.import_models()
  File "C:\Program Files (x86)\Python37-32\lib\site-packages\django\apps\config.py", line 198, in import_models
    self.models_module = import_module(models_module_name)
  File "C:\Program Files (x86)\Python37-32\lib\importlib\__init__.py", line 127, in import_module
    return _bootstrap._gcd_import(name[level:], package, level)
  File "<frozen importlib._bootstrap>", line 1006, in _gcd_import
  File "<frozen importlib._bootstrap>", line 983, in _find_and_load
  File "<frozen importlib._bootstrap>", line 967, in _find_and_load_unlocked
  File "<frozen importlib._bootstrap>", line 677, in _load_unlocked
  File "<frozen importlib._bootstrap_external>", line 724, in exec_module
  File "<frozen importlib._bootstrap_external>", line 860, in get_code
  File "<frozen importlib._bootstrap_external>", line 791, in source_to_code
  File "<frozen importlib._bootstrap>", line 219, in _call_with_frames_removed
  File "C:\Users\J-Coders-Pc4\Desktop\ditari\home\models.py", line 28
    mbiemriNx=models.CharField(max_length=50)
                                            ^
IndentationError: unindent does not match any outer indentation level
Unhandled exception in thread started by <function check_errors.<locals>.wrapper at 0x038006F0>
Traceback (most recent call last):
  File "C:\Program Files (x86)\Python37-32\lib\site-packages\django\utils\autoreload.py", line 225, in wrapper
    fn(*args, **kwargs)
  File "C:\Program Files (x86)\Python37-32\lib\site-packages\django\core\management\commands\runserver.py", line 109, in inner_run
    autoreload.raise_last_exception()
  File "C:\Program Files (x86)\Python37-32\lib\site-packages\django\utils\autoreload.py", line 248, in raise_last_exception
    raise _exception[1]
  File "C:\Program Files (x86)\Python37-32\lib\site-packages\django\core\management\__init__.py", line 337, in execute
    autoreload.check_errors(django.setup)()
  File "C:\Program Files (x86)\Python37-32\lib\site-packages\django\utils\autoreload.py", line 225, in wrapper
    fn(*args, **kwargs)
  File "C:\Program Files (x86)\Python37-32\lib\site-packages\django\__init__.py", line 24, in setup
    apps.populate(settings.INSTALLED_APPS)
  File "C:\Program Files (x86)\Python37-32\lib\site-packages\django\apps\registry.py", line 112, in populate
    app_config.import_models()
  File "C:\Program Files (x86)\Python37-32\lib\site-packages\django\apps\config.py", line 198, in import_models
    self.models_module = import_module(models_module_name)
  File "C:\Program Files (x86)\Python37-32\lib\importlib\__init__.py", line 127, in import_module
    return _bootstrap._gcd_import(name[level:], package, level)
  File "<frozen importlib._bootstrap>", line 1006, in _gcd_import
  File "<frozen importlib._bootstrap>", line 983, in _find_and_load
  File "<frozen importlib._bootstrap>", line 967, in _find_and_load_unlocked
  File "<frozen importlib._bootstrap>", line 677, in _load_unlocked
  File "<frozen importlib._bootstrap_external>", line 724, in exec_module
  File "<frozen importlib._bootstrap_external>", line 860, in get_code
  File "<frozen importlib._bootstrap_external>", line 791, in source_to_code
  File "<frozen importlib._bootstrap>", line 219, in _call_with_frames_removed
  File "C:\Users\J-Coders-Pc4\Desktop\ditari\home\models.py", line 29
    emriPrindit=models.CharField(max_length=50)
                                              ^
IndentationError: unindent does not match any outer indentation level
Unhandled exception in thread started by <function check_errors.<locals>.wrapper at 0x0413B030>
Traceback (most recent call last):
  File "C:\Program Files (x86)\Python37-32\lib\site-packages\django\utils\autoreload.py", line 225, in wrapper
    fn(*args, **kwargs)
  File "C:\Program Files (x86)\Python37-32\lib\site-packages\django\core\management\commands\runserver.py", line 109, in inner_run
    autoreload.raise_last_exception()
  File "C:\Program Files (x86)\Python37-32\lib\site-packages\django\utils\autoreload.py", line 248, in raise_last_exception
    raise _exception[1]
  File "C:\Program Files (x86)\Python37-32\lib\site-packages\django\core\management\__init__.py", line 337, in execute
    autoreload.check_errors(django.setup)()
  File "C:\Program Files (x86)\Python37-32\lib\site-packages\django\utils\autoreload.py", line 225, in wrapper
    fn(*args, **kwargs)
  File "C:\Program Files (x86)\Python37-32\lib\site-packages\django\__init__.py", line 24, in setup
    apps.populate(settings.INSTALLED_APPS)
  File "C:\Program Files (x86)\Python37-32\lib\site-packages\django\apps\registry.py", line 112, in populate
    app_config.import_models()
  File "C:\Program Files (x86)\Python37-32\lib\site-packages\django\apps\config.py", line 198, in import_models
    self.models_module = import_module(models_module_name)
  File "C:\Program Files (x86)\Python37-32\lib\importlib\__init__.py", line 127, in import_module
    return _bootstrap._gcd_import(name[level:], package, level)
  File "<frozen importlib._bootstrap>", line 1006, in _gcd_import
  File "<frozen importlib._bootstrap>", line 983, in _find_and_load
  File "<frozen importlib._bootstrap>", line 967, in _find_and_load_unlocked
  File "<frozen importlib._bootstrap>", line 677, in _load_unlocked
  File "<frozen importlib._bootstrap_external>", line 724, in exec_module
  File "<frozen importlib._bootstrap_external>", line 860, in get_code
  File "<frozen importlib._bootstrap_external>", line 791, in source_to_code
  File "<frozen importlib._bootstrap>", line 219, in _call_with_frames_removed
  File "C:\Users\J-Coders-Pc4\Desktop\ditari\home\models.py", line 32
    def __str__(self):
                     ^
IndentationError: unindent does not match any outer indentation level
Unhandled exception in thread started by <function check_errors.<locals>.wrapper at 0x03B570C0>
Traceback (most recent call last):
  File "C:\Program Files (x86)\Python37-32\lib\site-packages\django\utils\autoreload.py", line 225, in wrapper
    fn(*args, **kwargs)
  File "C:\Program Files (x86)\Python37-32\lib\site-packages\django\core\management\commands\runserver.py", line 109, in inner_run
    autoreload.raise_last_exception()
  File "C:\Program Files (x86)\Python37-32\lib\site-packages\django\utils\autoreload.py", line 248, in raise_last_exception
    raise _exception[1]
  File "C:\Program Files (x86)\Python37-32\lib\site-packages\django\core\management\__init__.py", line 337, in execute
    autoreload.check_errors(django.setup)()
  File "C:\Program Files (x86)\Python37-32\lib\site-packages\django\utils\autoreload.py", line 225, in wrapper
    fn(*args, **kwargs)
  File "C:\Program Files (x86)\Python37-32\lib\site-packages\django\__init__.py", line 24, in setup
    apps.populate(settings.INSTALLED_APPS)
  File "C:\Program Files (x86)\Python37-32\lib\site-packages\django\apps\registry.py", line 112, in populate
    app_config.import_models()
  File "C:\Program Files (x86)\Python37-32\lib\site-packages\django\apps\config.py", line 198, in import_models
    self.models_module = import_module(models_module_name)
  File "C:\Program Files (x86)\Python37-32\lib\importlib\__init__.py", line 127, in import_module
    return _bootstrap._gcd_import(name[level:], package, level)
  File "<frozen importlib._bootstrap>", line 1006, in _gcd_import
  File "<frozen importlib._bootstrap>", line 983, in _find_and_load
  File "<frozen importlib._bootstrap>", line 967, in _find_and_load_unlocked
  File "<frozen importlib._bootstrap>", line 677, in _load_unlocked
  File "<frozen importlib._bootstrap_external>", line 724, in exec_module
  File "<frozen importlib._bootstrap_external>", line 860, in get_code
  File "<frozen importlib._bootstrap_external>", line 791, in source_to_code
  File "<frozen importlib._bootstrap>", line 219, in _call_with_frames_removed
  File "C:\Users\J-Coders-Pc4\Desktop\ditari\home\models.py", line 33
    return.self.emriNx+" "+self.mbiemriNx
          ^
SyntaxError: invalid syntax
Performing system checks...

System check identified no issues (0 silenced).
January 14, 2019 - 15:37:51
Django version 2.1.5, using settings 'ditari.settings'
Starting development server at http://127.0.0.1:8000/
Quit the server with CTRL-BREAK.

C:\Users\J-Coders-Pc4\Desktop\ditari>python manage.py makemigrations
Migrations for 'home':
  home\migrations\0005_nxenesi.py
    - Create model nxenesi

C:\Users\J-Coders-Pc4\Desktop\ditari>python manage.py migrate
Operations to perform:
  Apply all migrations: admin, auth, contenttypes, home, sessions
Running migrations:
  Applying home.0005_nxenesi... OK

C:\Users\J-Coders-Pc4\Desktop\ditari>python manage.py runserver
Performing system checks...

System check identified no issues (0 silenced).
January 14, 2019 - 15:38:20
Django version 2.1.5, using settings 'ditari.settings'
Starting development server at http://127.0.0.1:8000/
Quit the server with CTRL-BREAK.
[14/Jan/2019 15:38:26] "GET /admin/home/klasa/add/ HTTP/1.1" 200 6686
[14/Jan/2019 15:38:26] "GET /admin/jsi18n/ HTTP/1.1" 200 3185
[14/Jan/2019 15:38:45] "POST /admin/home/klasa/add/ HTTP/1.1" 302 0
[14/Jan/2019 15:38:45] "GET /admin/home/klasa/ HTTP/1.1" 200 4482
[14/Jan/2019 15:38:45] "GET /admin/jsi18n/ HTTP/1.1" 200 3185
[14/Jan/2019 15:38:49] "GET /admin/home/ HTTP/1.1" 200 3704
[14/Jan/2019 15:38:50] "GET /admin/home/nxenesi/ HTTP/1.1" 200 3168
[14/Jan/2019 15:38:50] "GET /admin/jsi18n/ HTTP/1.1" 200 3185
[14/Jan/2019 15:38:51] "GET /admin/home/nxenesi/add/ HTTP/1.1" 200 6587
[14/Jan/2019 15:38:51] "GET /admin/jsi18n/ HTTP/1.1" 200 3185
[14/Jan/2019 15:39:23] "POST /admin/home/nxenesi/add/ HTTP/1.1" 302 0
[14/Jan/2019 15:39:23] "GET /admin/home/nxenesi/ HTTP/1.1" 200 4520
[14/Jan/2019 15:39:23] "GET /admin/jsi18n/ HTTP/1.1" 200 3185
Performing system checks...

System check identified no issues (0 silenced).
January 14, 2019 - 15:40:51
Django version 2.1.5, using settings 'ditari.settings'
Starting development server at http://127.0.0.1:8000/
Quit the server with CTRL-BREAK.
Performing system checks...

System check identified no issues (0 silenced).
January 14, 2019 - 15:41:29
Django version 2.1.5, using settings 'ditari.settings'
Starting development server at http://127.0.0.1:8000/
Quit the server with CTRL-BREAK.

C:\Users\J-Coders-Pc4\Desktop\ditari>

C:\Users\J-Coders-Pc4\Desktop\ditari>
C:\Users\J-Coders-Pc4\Desktop\ditari>python manage.py makemigrations
Migrations for 'home':
  home\migrations\0006_perioda.py
    - Create model perioda

C:\Users\J-Coders-Pc4\Desktop\ditari>python manage.py migrate
Operations to perform:
  Apply all migrations: admin, auth, contenttypes, home, sessions
Running migrations:
  Applying home.0006_perioda... OK

C:\Users\J-Coders-Pc4\Desktop\ditari>python manage.py runserver
Performing system checks...

System check identified no issues (0 silenced).
January 14, 2019 - 15:43:26
Django version 2.1.5, using settings 'ditari.settings'
Starting development server at http://127.0.0.1:8000/
Quit the server with CTRL-BREAK.
[14/Jan/2019 15:43:30] "GET /admin/home/nxenesi/ HTTP/1.1" 200 4335
[14/Jan/2019 15:43:30] "GET /admin/jsi18n/ HTTP/1.1" 200 3185
[14/Jan/2019 15:43:32] "GET /admin/ HTTP/1.1" 200 6177
Performing system checks...

System check identified no issues (0 silenced).
January 14, 2019 - 15:44:22
Django version 2.1.5, using settings 'ditari.settings'
Starting development server at http://127.0.0.1:8000/
Quit the server with CTRL-BREAK.
[14/Jan/2019 15:44:29] "GET /admin/ HTTP/1.1" 200 6608
Performing system checks...

System check identified no issues (0 silenced).
January 14, 2019 - 15:44:59
Django version 2.1.5, using settings 'ditari.settings'
Starting development server at http://127.0.0.1:8000/
Quit the server with CTRL-BREAK.
Unhandled exception in thread started by <function check_errors.<locals>.wrapper at 0x03D3A108>
Traceback (most recent call last):
  File "C:\Program Files (x86)\Python37-32\lib\site-packages\django\utils\autoreload.py", line 225, in wrapper
    fn(*args, **kwargs)
  File "C:\Program Files (x86)\Python37-32\lib\site-packages\django\core\management\commands\runserver.py", line 109, in inner_run
    autoreload.raise_last_exception()
  File "C:\Program Files (x86)\Python37-32\lib\site-packages\django\utils\autoreload.py", line 248, in raise_last_exception
    raise _exception[1]
  File "C:\Program Files (x86)\Python37-32\lib\site-packages\django\core\management\__init__.py", line 337, in execute
    autoreload.check_errors(django.setup)()
  File "C:\Program Files (x86)\Python37-32\lib\site-packages\django\utils\autoreload.py", line 225, in wrapper
    fn(*args, **kwargs)
  File "C:\Program Files (x86)\Python37-32\lib\site-packages\django\__init__.py", line 24, in setup
    apps.populate(settings.INSTALLED_APPS)
  File "C:\Program Files (x86)\Python37-32\lib\site-packages\django\apps\registry.py", line 120, in populate
    app_config.ready()
  File "C:\Program Files (x86)\Python37-32\lib\site-packages\django\contrib\admin\apps.py", line 24, in ready
    self.module.autodiscover()
  File "C:\Program Files (x86)\Python37-32\lib\site-packages\django\contrib\admin\__init__.py", line 26, in autodiscover
    autodiscover_modules('admin', register_to=site)
  File "C:\Program Files (x86)\Python37-32\lib\site-packages\django\utils\module_loading.py", line 47, in autodiscover_modules
    import_module('%s.%s' % (app_config.name, module_to_search))
  File "C:\Program Files (x86)\Python37-32\lib\importlib\__init__.py", line 127, in import_module
    return _bootstrap._gcd_import(name[level:], package, level)
  File "<frozen importlib._bootstrap>", line 1006, in _gcd_import
  File "<frozen importlib._bootstrap>", line 983, in _find_and_load
  File "<frozen importlib._bootstrap>", line 967, in _find_and_load_unlocked
  File "<frozen importlib._bootstrap>", line 677, in _load_unlocked
  File "<frozen importlib._bootstrap_external>", line 728, in exec_module
  File "<frozen importlib._bootstrap>", line 219, in _call_with_frames_removed
  File "C:\Users\J-Coders-Pc4\Desktop\ditari\home\admin.py", line 3, in <module>
    from .models import lenda,profesori,klasa,nxenesi,perioda,nota
ImportError: cannot import name 'nota' from 'home.models' (C:\Users\J-Coders-Pc4\Desktop\ditari\home\models.py)
Performing system checks...

System check identified no issues (0 silenced).
January 14, 2019 - 15:58:35
Django version 2.1.5, using settings 'ditari.settings'
Starting development server at http://127.0.0.1:8000/
Quit the server with CTRL-BREAK.
Performing system checks...

System check identified no issues (0 silenced).
January 14, 2019 - 16:03:39
Django version 2.1.5, using settings 'ditari.settings'
Starting development server at http://127.0.0.1:8000/
Quit the server with CTRL-BREAK.

C:\Users\J-Coders-Pc4\Desktop\ditari>python manage.py makemigrations
Migrations for 'home':
  home\migrations\0007_nota.py
    - Create model nota

C:\Users\J-Coders-Pc4\Desktop\ditari>

C:\Users\J-Coders-Pc4\Desktop\ditari>python manage.py migrate
Operations to perform:
  Apply all migrations: admin, auth, contenttypes, home, sessions
Running migrations:
  Applying home.0007_nota... OK

C:\Users\J-Coders-Pc4\Desktop\ditari>python manage.py runserver
Performing system checks...

System check identified no issues (0 silenced).
January 14, 2019 - 16:04:53
Django version 2.1.5, using settings 'ditari.settings'
Starting development server at http://127.0.0.1:8000/
Quit the server with CTRL-BREAK.
[14/Jan/2019 16:04:57] "GET /admin/ HTTP/1.1" 200 7024
[14/Jan/2019 16:05:05] "GET /admin/home/nota/ HTTP/1.1" 200 3147
[14/Jan/2019 16:05:05] "GET /admin/jsi18n/ HTTP/1.1" 200 3185
[14/Jan/2019 16:05:07] "GET /admin/home/nota/add/ HTTP/1.1" 200 6221
[14/Jan/2019 16:05:07] "GET /admin/jsi18n/ HTTP/1.1" 200 3185
Performing system checks...

System check identified no issues (0 silenced).
January 14, 2019 - 16:05:27
Django version 2.1.5, using settings 'ditari.settings'
Starting development server at http://127.0.0.1:8000/
Quit the server with CTRL-BREAK.

C:\Users\J-Coders-Pc4\Desktop\ditari>python manage.py makemigrations
Migrations for 'home':
  home\migrations\0008_auto_20190114_1605.py
    - Add field IdPerioda to nota
    - Add field idLenda to nota

C:\Users\J-Coders-Pc4\Desktop\ditari>

C:\Users\J-Coders-Pc4\Desktop\ditari>python manage.py migrate
Operations to perform:
  Apply all migrations: admin, auth, contenttypes, home, sessions
Running migrations:
  Applying home.0008_auto_20190114_1605... OK

C:\Users\J-Coders-Pc4\Desktop\ditari>

C:\Users\J-Coders-Pc4\Desktop\ditari>python manage.py runserver
Performing system checks...

System check identified no issues (0 silenced).
January 14, 2019 - 16:05:52
Django version 2.1.5, using settings 'ditari.settings'
Starting development server at http://127.0.0.1:8000/
Quit the server with CTRL-BREAK.
[14/Jan/2019 16:05:55] "GET /admin/home/nota/add/ HTTP/1.1" 200 8359
[14/Jan/2019 16:05:55] "GET /admin/jsi18n/ HTTP/1.1" 200 3185
Performing system checks...

System check identified no issues (0 silenced).
January 14, 2019 - 16:07:39
Django version 2.1.5, using settings 'ditari.settings'
Starting development server at http://127.0.0.1:8000/
Quit the server with CTRL-BREAK.
[14/Jan/2019 16:07:42] "GET /admin/home/nota/add/ HTTP/1.1" 200 8359
[14/Jan/2019 16:07:42] "GET /admin/jsi18n/ HTTP/1.1" 200 3185
Performing system checks...

System check identified no issues (0 silenced).
January 14, 2019 - 16:09:25
Django version 2.1.5, using settings 'ditari.settings'
Starting development server at http://127.0.0.1:8000/
Quit the server with CTRL-BREAK.
[14/Jan/2019 16:09:42] "GET /admin/home/nota/add/ HTTP/1.1" 200 8359
[14/Jan/2019 16:09:42] "GET /admin/jsi18n/ HTTP/1.1" 200 3185

C:\Users\J-Coders-Pc4\Desktop\ditari>python manage.py makemigrations
Migrations for 'home':
  home\migrations\0009_auto_20190114_1610.py
    - Alter field IdPerioda on nota

C:\Users\J-Coders-Pc4\Desktop\ditari>python manage.py migrate
Operations to perform:
  Apply all migrations: admin, auth, contenttypes, home, sessions
Running migrations:
  Applying home.0009_auto_20190114_1610... OK

C:\Users\J-Coders-Pc4\Desktop\ditari>python manage.py runserver
Performing system checks...

System check identified no issues (0 silenced).
January 14, 2019 - 16:10:23
Django version 2.1.5, using settings 'ditari.settings'
Starting development server at http://127.0.0.1:8000/
Quit the server with CTRL-BREAK.
[14/Jan/2019 16:10:25] "GET /admin/home/nota/add/ HTTP/1.1" 200 8359
[14/Jan/2019 16:10:25] "GET /admin/jsi18n/ HTTP/1.1" 200 3185
[14/Jan/2019 16:12:48] "GET /admin/home/ HTTP/1.1" 200 4551
[14/Jan/2019 16:12:49] "GET /admin/home/perioda/ HTTP/1.1" 200 3168
[14/Jan/2019 16:12:49] "GET /admin/jsi18n/ HTTP/1.1" 200 3185
[14/Jan/2019 16:12:51] "GET /admin/home/perioda/add/ HTTP/1.1" 200 4005
[14/Jan/2019 16:12:51] "GET /admin/jsi18n/ HTTP/1.1" 200 3185
[14/Jan/2019 16:13:00] "POST /admin/home/perioda/add/ HTTP/1.1" 302 0
[14/Jan/2019 16:13:00] "GET /admin/home/perioda/ HTTP/1.1" 200 4514
[14/Jan/2019 16:13:00] "GET /admin/jsi18n/ HTTP/1.1" 200 3185
[14/Jan/2019 16:13:02] "GET /admin/home/ HTTP/1.1" 200 4551
[14/Jan/2019 16:13:03] "GET /admin/home/nota/ HTTP/1.1" 200 3147
[14/Jan/2019 16:13:03] "GET /admin/jsi18n/ HTTP/1.1" 200 3185
[14/Jan/2019 16:13:05] "GET /admin/home/nota/add/ HTTP/1.1" 200 8407
[14/Jan/2019 16:13:05] "GET /admin/jsi18n/ HTTP/1.1" 200 3185
Internal Server Error: /admin/home/nota/add/
Traceback (most recent call last):
  File "C:\Program Files (x86)\Python37-32\lib\site-packages\django\core\handlers\exception.py", line 34, in inner
    response = get_response(request)
  File "C:\Program Files (x86)\Python37-32\lib\site-packages\django\core\handlers\base.py", line 126, in _get_response
    response = self.process_exception_by_middleware(e, request)
  File "C:\Program Files (x86)\Python37-32\lib\site-packages\django\core\handlers\base.py", line 124, in _get_response
    response = wrapped_callback(request, *callback_args, **callback_kwargs)
  File "C:\Program Files (x86)\Python37-32\lib\site-packages\django\contrib\admin\options.py", line 604, in wrapper
    return self.admin_site.admin_view(view)(*args, **kwargs)
  File "C:\Program Files (x86)\Python37-32\lib\site-packages\django\utils\decorators.py", line 142, in _wrapped_view
    response = view_func(request, *args, **kwargs)
  File "C:\Program Files (x86)\Python37-32\lib\site-packages\django\views\decorators\cache.py", line 44, in _wrapped_view_func
    response = view_func(request, *args, **kwargs)
  File "C:\Program Files (x86)\Python37-32\lib\site-packages\django\contrib\admin\sites.py", line 223, in inner
    return view(request, *args, **kwargs)
  File "C:\Program Files (x86)\Python37-32\lib\site-packages\django\contrib\admin\options.py", line 1637, in add_view
    return self.changeform_view(request, None, form_url, extra_context)
  File "C:\Program Files (x86)\Python37-32\lib\site-packages\django\utils\decorators.py", line 45, in _wrapper
    return bound_method(*args, **kwargs)
  File "C:\Program Files (x86)\Python37-32\lib\site-packages\django\utils\decorators.py", line 142, in _wrapped_view
    response = view_func(request, *args, **kwargs)
  File "C:\Program Files (x86)\Python37-32\lib\site-packages\django\contrib\admin\options.py", line 1525, in changeform_view
    return self._changeform_view(request, object_id, form_url, extra_context)
  File "C:\Program Files (x86)\Python37-32\lib\site-packages\django\contrib\admin\options.py", line 1568, in _changeform_view
    self.log_addition(request, new_object, change_message)
  File "C:\Program Files (x86)\Python37-32\lib\site-packages\django\contrib\admin\options.py", line 808, in log_addition
    object_repr=str(object),
  File "C:\Users\J-Coders-Pc4\Desktop\ditari\home\models.py", line 45, in __str__
    vlera=str(vlera)
UnboundLocalError: local variable 'vlera' referenced before assignment
[14/Jan/2019 16:13:16] "POST /admin/home/nota/add/ HTTP/1.1" 500 112115
Performing system checks...

System check identified no issues (0 silenced).
January 14, 2019 - 16:15:51
Django version 2.1.5, using settings 'ditari.settings'
Starting development server at http://127.0.0.1:8000/
Quit the server with CTRL-BREAK.

C:\Users\J-Coders-Pc4\Desktop\ditari>python manage.py makemigrations
No changes detected

C:\Users\J-Coders-Pc4\Desktop\ditari>python manage.py migrate
Operations to perform:
  Apply all migrations: admin, auth, contenttypes, home, sessions
Running migrations:
  No migrations to apply.

C:\Users\J-Coders-Pc4\Desktop\ditari>python manage.py runserver
Performing system checks...

System check identified no issues (0 silenced).
January 14, 2019 - 16:16:15
Django version 2.1.5, using settings 'ditari.settings'
Starting development server at http://127.0.0.1:8000/
Quit the server with CTRL-BREAK.
Internal Server Error: /admin/home/nota/add/
Traceback (most recent call last):
  File "C:\Program Files (x86)\Python37-32\lib\site-packages\django\core\handlers\exception.py", line 34, in inner
    response = get_response(request)
  File "C:\Program Files (x86)\Python37-32\lib\site-packages\django\core\handlers\base.py", line 126, in _get_response
    response = self.process_exception_by_middleware(e, request)
  File "C:\Program Files (x86)\Python37-32\lib\site-packages\django\core\handlers\base.py", line 124, in _get_response
    response = wrapped_callback(request, *callback_args, **callback_kwargs)
  File "C:\Program Files (x86)\Python37-32\lib\site-packages\django\contrib\admin\options.py", line 604, in wrapper
    return self.admin_site.admin_view(view)(*args, **kwargs)
  File "C:\Program Files (x86)\Python37-32\lib\site-packages\django\utils\decorators.py", line 142, in _wrapped_view
    response = view_func(request, *args, **kwargs)
  File "C:\Program Files (x86)\Python37-32\lib\site-packages\django\views\decorators\cache.py", line 44, in _wrapped_view_func
    response = view_func(request, *args, **kwargs)
  File "C:\Program Files (x86)\Python37-32\lib\site-packages\django\contrib\admin\sites.py", line 223, in inner
    return view(request, *args, **kwargs)
  File "C:\Program Files (x86)\Python37-32\lib\site-packages\django\contrib\admin\options.py", line 1637, in add_view
    return self.changeform_view(request, None, form_url, extra_context)
  File "C:\Program Files (x86)\Python37-32\lib\site-packages\django\utils\decorators.py", line 45, in _wrapper
    return bound_method(*args, **kwargs)
  File "C:\Program Files (x86)\Python37-32\lib\site-packages\django\utils\decorators.py", line 142, in _wrapped_view
    response = view_func(request, *args, **kwargs)
  File "C:\Program Files (x86)\Python37-32\lib\site-packages\django\contrib\admin\options.py", line 1525, in changeform_view
    return self._changeform_view(request, object_id, form_url, extra_context)
  File "C:\Program Files (x86)\Python37-32\lib\site-packages\django\contrib\admin\options.py", line 1568, in _changeform_view
    self.log_addition(request, new_object, change_message)
  File "C:\Program Files (x86)\Python37-32\lib\site-packages\django\contrib\admin\options.py", line 808, in log_addition
    object_repr=str(object),
TypeError: __str__ returned non-string (type int)
[14/Jan/2019 16:16:19] "POST /admin/home/nota/add/ HTTP/1.1" 500 108658
Performing system checks...

System check identified no issues (0 silenced).
January 14, 2019 - 16:17:49
Django version 2.1.5, using settings 'ditari.settings'
Starting development server at http://127.0.0.1:8000/
Quit the server with CTRL-BREAK.
Performing system checks...

System check identified no issues (0 silenced).
January 14, 2019 - 16:17:58
Django version 2.1.5, using settings 'ditari.settings'
Starting development server at http://127.0.0.1:8000/
Quit the server with CTRL-BREAK.

C:\Users\J-Coders-Pc4\Desktop\ditari>python manage.py makemigrations
No changes detected

C:\Users\J-Coders-Pc4\Desktop\ditari>python manage.py migrate
Operations to perform:
  Apply all migrations: admin, auth, contenttypes, home, sessions
Running migrations:
  No migrations to apply.

C:\Users\J-Coders-Pc4\Desktop\ditari>python manage.py runserver
Performing system checks...

System check identified no issues (0 silenced).
January 14, 2019 - 16:18:11
Django version 2.1.5, using settings 'ditari.settings'
Starting development server at http://127.0.0.1:8000/
Quit the server with CTRL-BREAK.
Internal Server Error: /admin/home/nota/add/
Traceback (most recent call last):
  File "C:\Program Files (x86)\Python37-32\lib\site-packages\django\core\handlers\exception.py", line 34, in inner
    response = get_response(request)
  File "C:\Program Files (x86)\Python37-32\lib\site-packages\django\core\handlers\base.py", line 126, in _get_response
    response = self.process_exception_by_middleware(e, request)
  File "C:\Program Files (x86)\Python37-32\lib\site-packages\django\core\handlers\base.py", line 124, in _get_response
    response = wrapped_callback(request, *callback_args, **callback_kwargs)
  File "C:\Program Files (x86)\Python37-32\lib\site-packages\django\contrib\admin\options.py", line 604, in wrapper
    return self.admin_site.admin_view(view)(*args, **kwargs)
  File "C:\Program Files (x86)\Python37-32\lib\site-packages\django\utils\decorators.py", line 142, in _wrapped_view
    response = view_func(request, *args, **kwargs)
  File "C:\Program Files (x86)\Python37-32\lib\site-packages\django\views\decorators\cache.py", line 44, in _wrapped_view_func
    response = view_func(request, *args, **kwargs)
  File "C:\Program Files (x86)\Python37-32\lib\site-packages\django\contrib\admin\sites.py", line 223, in inner
    return view(request, *args, **kwargs)
  File "C:\Program Files (x86)\Python37-32\lib\site-packages\django\contrib\admin\options.py", line 1637, in add_view
    return self.changeform_view(request, None, form_url, extra_context)
  File "C:\Program Files (x86)\Python37-32\lib\site-packages\django\utils\decorators.py", line 45, in _wrapper
    return bound_method(*args, **kwargs)
  File "C:\Program Files (x86)\Python37-32\lib\site-packages\django\utils\decorators.py", line 142, in _wrapped_view
    response = view_func(request, *args, **kwargs)
  File "C:\Program Files (x86)\Python37-32\lib\site-packages\django\contrib\admin\options.py", line 1525, in changeform_view
    return self._changeform_view(request, object_id, form_url, extra_context)
  File "C:\Program Files (x86)\Python37-32\lib\site-packages\django\contrib\admin\options.py", line 1568, in _changeform_view
    self.log_addition(request, new_object, change_message)
  File "C:\Program Files (x86)\Python37-32\lib\site-packages\django\contrib\admin\options.py", line 808, in log_addition
    object_repr=str(object),
TypeError: __str__ returned non-string (type int)
[14/Jan/2019 16:18:30] "POST /admin/home/nota/add/ HTTP/1.1" 500 108658
Internal Server Error: /admin/home/nota/add/
Traceback (most recent call last):
  File "C:\Program Files (x86)\Python37-32\lib\site-packages\django\core\handlers\exception.py", line 34, in inner
    response = get_response(request)
  File "C:\Program Files (x86)\Python37-32\lib\site-packages\django\core\handlers\base.py", line 126, in _get_response
    response = self.process_exception_by_middleware(e, request)
  File "C:\Program Files (x86)\Python37-32\lib\site-packages\django\core\handlers\base.py", line 124, in _get_response
    response = wrapped_callback(request, *callback_args, **callback_kwargs)
  File "C:\Program Files (x86)\Python37-32\lib\site-packages\django\contrib\admin\options.py", line 604, in wrapper
    return self.admin_site.admin_view(view)(*args, **kwargs)
  File "C:\Program Files (x86)\Python37-32\lib\site-packages\django\utils\decorators.py", line 142, in _wrapped_view
    response = view_func(request, *args, **kwargs)
  File "C:\Program Files (x86)\Python37-32\lib\site-packages\django\views\decorators\cache.py", line 44, in _wrapped_view_func
    response = view_func(request, *args, **kwargs)
  File "C:\Program Files (x86)\Python37-32\lib\site-packages\django\contrib\admin\sites.py", line 223, in inner
    return view(request, *args, **kwargs)
  File "C:\Program Files (x86)\Python37-32\lib\site-packages\django\contrib\admin\options.py", line 1637, in add_view
    return self.changeform_view(request, None, form_url, extra_context)
  File "C:\Program Files (x86)\Python37-32\lib\site-packages\django\utils\decorators.py", line 45, in _wrapper
    return bound_method(*args, **kwargs)
  File "C:\Program Files (x86)\Python37-32\lib\site-packages\django\utils\decorators.py", line 142, in _wrapped_view
    response = view_func(request, *args, **kwargs)
  File "C:\Program Files (x86)\Python37-32\lib\site-packages\django\contrib\admin\options.py", line 1525, in changeform_view
    return self._changeform_view(request, object_id, form_url, extra_context)
  File "C:\Program Files (x86)\Python37-32\lib\site-packages\django\contrib\admin\options.py", line 1568, in _changeform_view
    self.log_addition(request, new_object, change_message)
  File "C:\Program Files (x86)\Python37-32\lib\site-packages\django\contrib\admin\options.py", line 808, in log_addition
    object_repr=str(object),
TypeError: __str__ returned non-string (type int)
[14/Jan/2019 16:18:35] "POST /admin/home/nota/add/ HTTP/1.1" 500 108658
Performing system checks...

System check identified no issues (0 silenced).
January 14, 2019 - 16:19:41
Django version 2.1.5, using settings 'ditari.settings'
Starting development server at http://127.0.0.1:8000/
Quit the server with CTRL-BREAK.
Internal Server Error: /admin/home/nota/add/
Traceback (most recent call last):
  File "C:\Program Files (x86)\Python37-32\lib\site-packages\django\core\handlers\exception.py", line 34, in inner
    response = get_response(request)
  File "C:\Program Files (x86)\Python37-32\lib\site-packages\django\core\handlers\base.py", line 126, in _get_response
    response = self.process_exception_by_middleware(e, request)
  File "C:\Program Files (x86)\Python37-32\lib\site-packages\django\core\handlers\base.py", line 124, in _get_response
    response = wrapped_callback(request, *callback_args, **callback_kwargs)
  File "C:\Program Files (x86)\Python37-32\lib\site-packages\django\contrib\admin\options.py", line 604, in wrapper
    return self.admin_site.admin_view(view)(*args, **kwargs)
  File "C:\Program Files (x86)\Python37-32\lib\site-packages\django\utils\decorators.py", line 142, in _wrapped_view
    response = view_func(request, *args, **kwargs)
  File "C:\Program Files (x86)\Python37-32\lib\site-packages\django\views\decorators\cache.py", line 44, in _wrapped_view_func
    response = view_func(request, *args, **kwargs)
  File "C:\Program Files (x86)\Python37-32\lib\site-packages\django\contrib\admin\sites.py", line 223, in inner
    return view(request, *args, **kwargs)
  File "C:\Program Files (x86)\Python37-32\lib\site-packages\django\contrib\admin\options.py", line 1637, in add_view
    return self.changeform_view(request, None, form_url, extra_context)
  File "C:\Program Files (x86)\Python37-32\lib\site-packages\django\utils\decorators.py", line 45, in _wrapper
    return bound_method(*args, **kwargs)
  File "C:\Program Files (x86)\Python37-32\lib\site-packages\django\utils\decorators.py", line 142, in _wrapped_view
    response = view_func(request, *args, **kwargs)
  File "C:\Program Files (x86)\Python37-32\lib\site-packages\django\contrib\admin\options.py", line 1525, in changeform_view
    return self._changeform_view(request, object_id, form_url, extra_context)
  File "C:\Program Files (x86)\Python37-32\lib\site-packages\django\contrib\admin\options.py", line 1568, in _changeform_view
    self.log_addition(request, new_object, change_message)
  File "C:\Program Files (x86)\Python37-32\lib\site-packages\django\contrib\admin\options.py", line 808, in log_addition
    object_repr=str(object),
TypeError: __str__ returned non-string (type int)
[14/Jan/2019 16:19:44] "POST /admin/home/nota/add/ HTTP/1.1" 500 108658
Internal Server Error: /admin/home/nota/add/
Traceback (most recent call last):
  File "C:\Program Files (x86)\Python37-32\lib\site-packages\django\core\handlers\exception.py", line 34, in inner
    response = get_response(request)
  File "C:\Program Files (x86)\Python37-32\lib\site-packages\django\core\handlers\base.py", line 126, in _get_response
    response = self.process_exception_by_middleware(e, request)
  File "C:\Program Files (x86)\Python37-32\lib\site-packages\django\core\handlers\base.py", line 124, in _get_response
    response = wrapped_callback(request, *callback_args, **callback_kwargs)
  File "C:\Program Files (x86)\Python37-32\lib\site-packages\django\contrib\admin\options.py", line 604, in wrapper
    return self.admin_site.admin_view(view)(*args, **kwargs)
  File "C:\Program Files (x86)\Python37-32\lib\site-packages\django\utils\decorators.py", line 142, in _wrapped_view
    response = view_func(request, *args, **kwargs)
  File "C:\Program Files (x86)\Python37-32\lib\site-packages\django\views\decorators\cache.py", line 44, in _wrapped_view_func
    response = view_func(request, *args, **kwargs)
  File "C:\Program Files (x86)\Python37-32\lib\site-packages\django\contrib\admin\sites.py", line 223, in inner
    return view(request, *args, **kwargs)
  File "C:\Program Files (x86)\Python37-32\lib\site-packages\django\contrib\admin\options.py", line 1637, in add_view
    return self.changeform_view(request, None, form_url, extra_context)
  File "C:\Program Files (x86)\Python37-32\lib\site-packages\django\utils\decorators.py", line 45, in _wrapper
    return bound_method(*args, **kwargs)
  File "C:\Program Files (x86)\Python37-32\lib\site-packages\django\utils\decorators.py", line 142, in _wrapped_view
    response = view_func(request, *args, **kwargs)
  File "C:\Program Files (x86)\Python37-32\lib\site-packages\django\contrib\admin\options.py", line 1525, in changeform_view
    return self._changeform_view(request, object_id, form_url, extra_context)
  File "C:\Program Files (x86)\Python37-32\lib\site-packages\django\contrib\admin\options.py", line 1568, in _changeform_view
    self.log_addition(request, new_object, change_message)
  File "C:\Program Files (x86)\Python37-32\lib\site-packages\django\contrib\admin\options.py", line 808, in log_addition
    object_repr=str(object),
TypeError: __str__ returned non-string (type int)
[14/Jan/2019 16:19:48] "POST /admin/home/nota/add/ HTTP/1.1" 500 108658
[14/Jan/2019 16:20:00] "GET /admin/home/nota/add/ HTTP/1.1" 200 8417
Internal Server Error: /admin/home/nota/add/
Traceback (most recent call last):
  File "C:\Program Files (x86)\Python37-32\lib\site-packages\django\core\handlers\exception.py", line 34, in inner
    response = get_response(request)
  File "C:\Program Files (x86)\Python37-32\lib\site-packages\django\core\handlers\base.py", line 126, in _get_response
    response = self.process_exception_by_middleware(e, request)
  File "C:\Program Files (x86)\Python37-32\lib\site-packages\django\core\handlers\base.py", line 124, in _get_response
    response = wrapped_callback(request, *callback_args, **callback_kwargs)
  File "C:\Program Files (x86)\Python37-32\lib\site-packages\django\contrib\admin\options.py", line 604, in wrapper
    return self.admin_site.admin_view(view)(*args, **kwargs)
  File "C:\Program Files (x86)\Python37-32\lib\site-packages\django\utils\decorators.py", line 142, in _wrapped_view
    response = view_func(request, *args, **kwargs)
  File "C:\Program Files (x86)\Python37-32\lib\site-packages\django\views\decorators\cache.py", line 44, in _wrapped_view_func
    response = view_func(request, *args, **kwargs)
  File "C:\Program Files (x86)\Python37-32\lib\site-packages\django\contrib\admin\sites.py", line 223, in inner
    return view(request, *args, **kwargs)
  File "C:\Program Files (x86)\Python37-32\lib\site-packages\django\contrib\admin\options.py", line 1637, in add_view
    return self.changeform_view(request, None, form_url, extra_context)
  File "C:\Program Files (x86)\Python37-32\lib\site-packages\django\utils\decorators.py", line 45, in _wrapper
    return bound_method(*args, **kwargs)
  File "C:\Program Files (x86)\Python37-32\lib\site-packages\django\utils\decorators.py", line 142, in _wrapped_view
    response = view_func(request, *args, **kwargs)
  File "C:\Program Files (x86)\Python37-32\lib\site-packages\django\contrib\admin\options.py", line 1525, in changeform_view
    return self._changeform_view(request, object_id, form_url, extra_context)
  File "C:\Program Files (x86)\Python37-32\lib\site-packages\django\contrib\admin\options.py", line 1568, in _changeform_view
    self.log_addition(request, new_object, change_message)
  File "C:\Program Files (x86)\Python37-32\lib\site-packages\django\contrib\admin\options.py", line 808, in log_addition
    object_repr=str(object),
TypeError: __str__ returned non-string (type int)
[14/Jan/2019 16:20:02] "POST /admin/home/nota/add/ HTTP/1.1" 500 108658
Performing system checks...

System check identified no issues (0 silenced).
January 14, 2019 - 16:20:27
Django version 2.1.5, using settings 'ditari.settings'
Starting development server at http://127.0.0.1:8000/
Quit the server with CTRL-BREAK.
[14/Jan/2019 16:20:36] "GET /admin/home/nota/add/ HTTP/1.1" 200 8417
[14/Jan/2019 16:20:37] "GET /admin/home/ HTTP/1.1" 200 4551
[14/Jan/2019 16:20:40] "GET /admin/home/nota/ HTTP/1.1" 200 3147
[14/Jan/2019 16:20:40] "GET /admin/jsi18n/ HTTP/1.1" 200 3185
[14/Jan/2019 16:20:41] "GET /admin/home/nota/add/ HTTP/1.1" 200 8417
[14/Jan/2019 16:20:42] "GET /admin/jsi18n/ HTTP/1.1" 200 3185
Internal Server Error: /admin/home/nota/add/
Traceback (most recent call last):
  File "C:\Program Files (x86)\Python37-32\lib\site-packages\django\core\handlers\exception.py", line 34, in inner
    response = get_response(request)
  File "C:\Program Files (x86)\Python37-32\lib\site-packages\django\core\handlers\base.py", line 126, in _get_response
    response = self.process_exception_by_middleware(e, request)
  File "C:\Program Files (x86)\Python37-32\lib\site-packages\django\core\handlers\base.py", line 124, in _get_response
    response = wrapped_callback(request, *callback_args, **callback_kwargs)
  File "C:\Program Files (x86)\Python37-32\lib\site-packages\django\contrib\admin\options.py", line 604, in wrapper
    return self.admin_site.admin_view(view)(*args, **kwargs)
  File "C:\Program Files (x86)\Python37-32\lib\site-packages\django\utils\decorators.py", line 142, in _wrapped_view
    response = view_func(request, *args, **kwargs)
  File "C:\Program Files (x86)\Python37-32\lib\site-packages\django\views\decorators\cache.py", line 44, in _wrapped_view_func
    response = view_func(request, *args, **kwargs)
  File "C:\Program Files (x86)\Python37-32\lib\site-packages\django\contrib\admin\sites.py", line 223, in inner
    return view(request, *args, **kwargs)
  File "C:\Program Files (x86)\Python37-32\lib\site-packages\django\contrib\admin\options.py", line 1637, in add_view
    return self.changeform_view(request, None, form_url, extra_context)
  File "C:\Program Files (x86)\Python37-32\lib\site-packages\django\utils\decorators.py", line 45, in _wrapper
    return bound_method(*args, **kwargs)
  File "C:\Program Files (x86)\Python37-32\lib\site-packages\django\utils\decorators.py", line 142, in _wrapped_view
    response = view_func(request, *args, **kwargs)
  File "C:\Program Files (x86)\Python37-32\lib\site-packages\django\contrib\admin\options.py", line 1525, in changeform_view
    return self._changeform_view(request, object_id, form_url, extra_context)
  File "C:\Program Files (x86)\Python37-32\lib\site-packages\django\contrib\admin\options.py", line 1568, in _changeform_view
    self.log_addition(request, new_object, change_message)
  File "C:\Program Files (x86)\Python37-32\lib\site-packages\django\contrib\admin\options.py", line 808, in log_addition
    object_repr=str(object),
TypeError: __str__ returned non-string (type int)
[14/Jan/2019 16:20:50] "POST /admin/home/nota/add/ HTTP/1.1" 500 108658
Performing system checks...

System check identified no issues (0 silenced).
January 14, 2019 - 16:21:53
Django version 2.1.5, using settings 'ditari.settings'
Starting development server at http://127.0.0.1:8000/
Quit the server with CTRL-BREAK.

C:\Users\J-Coders-Pc4\Desktop\ditari>python manage.py makemigrations
Migrations for 'home':
  home\migrations\0010_auto_20190114_1622.py
    - Alter field vlera on nota

C:\Users\J-Coders-Pc4\Desktop\ditari>

C:\Users\J-Coders-Pc4\Desktop\ditari>python manage.py migrate
Operations to perform:
  Apply all migrations: admin, auth, contenttypes, home, sessions
Running migrations:
  Applying home.0010_auto_20190114_1622... OK

C:\Users\J-Coders-Pc4\Desktop\ditari>

C:\Users\J-Coders-Pc4\Desktop\ditari>python manage.py runserver
Performing system checks...

System check identified no issues (0 silenced).
January 14, 2019 - 16:22:13
Django version 2.1.5, using settings 'ditari.settings'
Starting development server at http://127.0.0.1:8000/
Quit the server with CTRL-BREAK.
[14/Jan/2019 16:22:17] "POST /admin/home/nota/add/ HTTP/1.1" 302 0
[14/Jan/2019 16:22:17] "GET /admin/home/nota/ HTTP/1.1" 200 4464
[14/Jan/2019 16:22:17] "GET /admin/jsi18n/ HTTP/1.1" 200 3185
Performing system checks...

System check identified no issues (0 silenced).
January 14, 2019 - 16:22:52
Django version 2.1.5, using settings 'ditari.settings'
Starting development server at http://127.0.0.1:8000/
Quit the server with CTRL-BREAK.
